2025-07-16 05:46:30,688 ERROR log Internal Server Error: /
Traceback (most recent call last):
  File "/usr/local/lib/python3.10/dist-packages/django/utils/datastructures.py", line 84, in __getitem__
    list_ = super().__getitem__(key)
KeyError: 'email'

During handling of the above exception, another exception occurred:

Traceback (most recent call last):
  File "/usr/local/lib/python3.10/dist-packages/django/core/handlers/exception.py", line 55, in inner
    response = get_response(request)
  File "/usr/local/lib/python3.10/dist-packages/django/core/handlers/base.py", line 197, in _get_response
    response = wrapped_callback(request, *callback_args, **callback_kwargs)
  File "/root/go-losdesign/losdesign/cabinet/views.py", line 46, in login_view
    email = request.POST['email']
  File "/usr/local/lib/python3.10/dist-packages/django/utils/datastructures.py", line 86, in __getitem__
    raise MultiValueDictKeyError(key)
django.utils.datastructures.MultiValueDictKeyError: 'email'
2025-07-22 19:38:10,254 ERROR log Internal Server Error: /
Traceback (most recent call last):
  File "/usr/local/lib/python3.10/dist-packages/django/utils/datastructures.py", line 84, in __getitem__
    list_ = super().__getitem__(key)
KeyError: 'email'

During handling of the above exception, another exception occurred:

Traceback (most recent call last):
  File "/usr/local/lib/python3.10/dist-packages/django/core/handlers/exception.py", line 55, in inner
    response = get_response(request)
  File "/usr/local/lib/python3.10/dist-packages/django/core/handlers/base.py", line 197, in _get_response
    response = wrapped_callback(request, *callback_args, **callback_kwargs)
  File "/root/go-losdesign/losdesign/cabinet/views.py", line 46, in login_view
    email = request.POST['email']
  File "/usr/local/lib/python3.10/dist-packages/django/utils/datastructures.py", line 86, in __getitem__
    raise MultiValueDictKeyError(key)
django.utils.datastructures.MultiValueDictKeyError: 'email'
